[2024-04-23T15:20:15.283+0000] {local_task_job_runner.py:120} INFO - ::group::Pre task execution logs
[2024-04-23T15:20:15.299+0000] {taskinstance.py:2073} INFO - Dependencies all met for dep_context=non-requeueable deps ti=<TaskInstance: dag_with_postgres_operator_v01.create_postgres_table scheduled__2024-04-21T00:00:00+00:00 [queued]>
[2024-04-23T15:20:15.303+0000] {taskinstance.py:2073} INFO - Dependencies all met for dep_context=requeueable deps ti=<TaskInstance: dag_with_postgres_operator_v01.create_postgres_table scheduled__2024-04-21T00:00:00+00:00 [queued]>
[2024-04-23T15:20:15.303+0000] {taskinstance.py:2303} INFO - Starting attempt 1 of 6
[2024-04-23T15:20:15.309+0000] {taskinstance.py:2327} INFO - Executing <Task(PostgresOperator): create_postgres_table> on 2024-04-21 00:00:00+00:00
[2024-04-23T15:20:15.312+0000] {standard_task_runner.py:90} INFO - Running: ['***', 'tasks', 'run', 'dag_with_postgres_operator_v01', 'create_postgres_table', 'scheduled__2024-04-21T00:00:00+00:00', '--job-id', '412', '--raw', '--subdir', 'DAGS_FOLDER/dag_with_postgres_operator.py', '--cfg-path', '/tmp/tmpq6tmf66d']
[2024-04-23T15:20:15.313+0000] {logging_mixin.py:188} WARNING - /home/***/.local/lib/python3.12/site-packages/***/task/task_runner/standard_task_runner.py:61 DeprecationWarning: This process (pid=1500) is multi-threaded, use of fork() may lead to deadlocks in the child.
[2024-04-23T15:20:15.314+0000] {standard_task_runner.py:91} INFO - Job 412: Subtask create_postgres_table
[2024-04-23T15:20:15.314+0000] {standard_task_runner.py:63} INFO - Started process 1502 to run task
[2024-04-23T15:20:15.335+0000] {task_command.py:426} INFO - Running <TaskInstance: dag_with_postgres_operator_v01.create_postgres_table scheduled__2024-04-21T00:00:00+00:00 [running]> on host e87e2f3305bd
[2024-04-23T15:20:15.371+0000] {taskinstance.py:2644} INFO - Exporting env vars: AIRFLOW_CTX_DAG_OWNER='julionevadod' AIRFLOW_CTX_DAG_ID='dag_with_postgres_operator_v01' AIRFLOW_CTX_TASK_ID='create_postgres_table' AIRFLOW_CTX_EXECUTION_DATE='2024-04-21T00:00:00+00:00' AIRFLOW_CTX_TRY_NUMBER='1' AIRFLOW_CTX_DAG_RUN_ID='scheduled__2024-04-21T00:00:00+00:00'
[2024-04-23T15:20:15.372+0000] {taskinstance.py:430} INFO - ::endgroup::
[2024-04-23T15:20:15.380+0000] {sql.py:276} INFO - Executing: 
            create table if not exists dag_runs (
            dt date,
            dag_id character varying,
            primary key (dt, dag_id)
            )
        
[2024-04-23T15:20:15.385+0000] {base.py:84} INFO - Using connection ID 'postgres_localhost' for task execution.
[2024-04-23T15:20:15.392+0000] {base.py:84} INFO - Using connection ID 'postgres_localhost' for task execution.
[2024-04-23T15:20:23.402+0000] {taskinstance.py:441} INFO - ::group::Post task execution logs
[2024-04-23T15:20:23.408+0000] {taskinstance.py:2890} ERROR - Task failed with exception
Traceback (most recent call last):
  File "/home/airflow/.local/lib/python3.12/site-packages/airflow/models/taskinstance.py", line 465, in _execute_task
    result = _execute_callable(context=context, **execute_callable_kwargs)
             ^^^^^^^^^^^^^^^^^^^^^^^^^^^^^^^^^^^^^^^^^^^^^^^^^^^^^^^^^^^^^
  File "/home/airflow/.local/lib/python3.12/site-packages/airflow/models/taskinstance.py", line 432, in _execute_callable
    return execute_callable(context=context, **execute_callable_kwargs)
           ^^^^^^^^^^^^^^^^^^^^^^^^^^^^^^^^^^^^^^^^^^^^^^^^^^^^^^^^^^^^
  File "/home/airflow/.local/lib/python3.12/site-packages/airflow/models/baseoperator.py", line 400, in wrapper
    return func(self, *args, **kwargs)
           ^^^^^^^^^^^^^^^^^^^^^^^^^^^
  File "/home/airflow/.local/lib/python3.12/site-packages/airflow/providers/common/sql/operators/sql.py", line 282, in execute
    output = hook.run(
             ^^^^^^^^^
  File "/home/airflow/.local/lib/python3.12/site-packages/airflow/providers/common/sql/hooks/sql.py", line 397, in run
    with closing(self.get_conn()) as conn:
                 ^^^^^^^^^^^^^^^
  File "/home/airflow/.local/lib/python3.12/site-packages/airflow/providers/postgres/hooks/postgres.py", line 161, in get_conn
    self.conn = psycopg2.connect(**conn_args)
                ^^^^^^^^^^^^^^^^^^^^^^^^^^^^^
  File "/home/airflow/.local/lib/python3.12/site-packages/psycopg2/__init__.py", line 122, in connect
    conn = _connect(dsn, connection_factory=connection_factory, **kwasync)
           ^^^^^^^^^^^^^^^^^^^^^^^^^^^^^^^^^^^^^^^^^^^^^^^^^^^^^^^^^^^^^^^
psycopg2.OperationalError: could not translate host name "host.docker.local" to address: Temporary failure in name resolution

[2024-04-23T15:20:23.431+0000] {taskinstance.py:1205} INFO - Marking task as UP_FOR_RETRY. dag_id=dag_with_postgres_operator_v01, task_id=create_postgres_table, execution_date=20240421T000000, start_date=20240423T152015, end_date=20240423T152023
[2024-04-23T15:20:23.448+0000] {standard_task_runner.py:110} ERROR - Failed to execute job 412 for task create_postgres_table (could not translate host name "host.docker.local" to address: Temporary failure in name resolution
; 1502)
[2024-04-23T15:20:23.483+0000] {local_task_job_runner.py:240} INFO - Task exited with return code 1
[2024-04-23T15:20:23.492+0000] {taskinstance.py:3482} INFO - 0 downstream tasks scheduled from follow-on schedule check
[2024-04-23T15:20:23.493+0000] {local_task_job_runner.py:222} INFO - ::endgroup::
[2024-04-23T15:23:36.640+0000] {local_task_job_runner.py:120} INFO - ::group::Pre task execution logs
[2024-04-23T15:23:36.657+0000] {taskinstance.py:2073} INFO - Dependencies all met for dep_context=non-requeueable deps ti=<TaskInstance: dag_with_postgres_operator_v01.create_postgres_table scheduled__2024-04-21T00:00:00+00:00 [queued]>
[2024-04-23T15:23:36.661+0000] {taskinstance.py:2073} INFO - Dependencies all met for dep_context=requeueable deps ti=<TaskInstance: dag_with_postgres_operator_v01.create_postgres_table scheduled__2024-04-21T00:00:00+00:00 [queued]>
[2024-04-23T15:23:36.661+0000] {taskinstance.py:2303} INFO - Starting attempt 1 of 6
[2024-04-23T15:23:36.667+0000] {taskinstance.py:2327} INFO - Executing <Task(PostgresOperator): create_postgres_table> on 2024-04-21 00:00:00+00:00
[2024-04-23T15:23:36.670+0000] {standard_task_runner.py:90} INFO - Running: ['***', 'tasks', 'run', 'dag_with_postgres_operator_v01', 'create_postgres_table', 'scheduled__2024-04-21T00:00:00+00:00', '--job-id', '414', '--raw', '--subdir', 'DAGS_FOLDER/dag_with_postgres_operator.py', '--cfg-path', '/tmp/tmpdy3tm3g5']
[2024-04-23T15:23:36.671+0000] {logging_mixin.py:188} WARNING - /home/***/.local/lib/python3.12/site-packages/***/task/task_runner/standard_task_runner.py:61 DeprecationWarning: This process (pid=1750) is multi-threaded, use of fork() may lead to deadlocks in the child.
[2024-04-23T15:23:36.672+0000] {standard_task_runner.py:91} INFO - Job 414: Subtask create_postgres_table
[2024-04-23T15:23:36.672+0000] {standard_task_runner.py:63} INFO - Started process 1752 to run task
[2024-04-23T15:23:36.701+0000] {task_command.py:426} INFO - Running <TaskInstance: dag_with_postgres_operator_v01.create_postgres_table scheduled__2024-04-21T00:00:00+00:00 [running]> on host e87e2f3305bd
[2024-04-23T15:23:36.741+0000] {taskinstance.py:2644} INFO - Exporting env vars: AIRFLOW_CTX_DAG_OWNER='julionevadod' AIRFLOW_CTX_DAG_ID='dag_with_postgres_operator_v01' AIRFLOW_CTX_TASK_ID='create_postgres_table' AIRFLOW_CTX_EXECUTION_DATE='2024-04-21T00:00:00+00:00' AIRFLOW_CTX_TRY_NUMBER='1' AIRFLOW_CTX_DAG_RUN_ID='scheduled__2024-04-21T00:00:00+00:00'
[2024-04-23T15:23:36.741+0000] {taskinstance.py:430} INFO - ::endgroup::
[2024-04-23T15:23:36.750+0000] {sql.py:276} INFO - Executing: 
            create table if not exists dag_runs (
            dt date,
            dag_id character varying,
            primary key (dt, dag_id)
            )
        
[2024-04-23T15:23:36.754+0000] {base.py:84} INFO - Using connection ID 'postgres_localhost' for task execution.
[2024-04-23T15:23:36.760+0000] {base.py:84} INFO - Using connection ID 'postgres_localhost' for task execution.
[2024-04-23T15:23:36.768+0000] {sql.py:457} INFO - Running statement: 
            create table if not exists dag_runs (
            dt date,
            dag_id character varying,
            primary key (dt, dag_id)
            )
        , parameters: None
[2024-04-23T15:23:36.780+0000] {taskinstance.py:441} INFO - ::group::Post task execution logs
[2024-04-23T15:23:36.781+0000] {taskinstance.py:2890} ERROR - Task failed with exception
Traceback (most recent call last):
  File "/home/airflow/.local/lib/python3.12/site-packages/airflow/models/taskinstance.py", line 465, in _execute_task
    result = _execute_callable(context=context, **execute_callable_kwargs)
             ^^^^^^^^^^^^^^^^^^^^^^^^^^^^^^^^^^^^^^^^^^^^^^^^^^^^^^^^^^^^^
  File "/home/airflow/.local/lib/python3.12/site-packages/airflow/models/taskinstance.py", line 432, in _execute_callable
    return execute_callable(context=context, **execute_callable_kwargs)
           ^^^^^^^^^^^^^^^^^^^^^^^^^^^^^^^^^^^^^^^^^^^^^^^^^^^^^^^^^^^^
  File "/home/airflow/.local/lib/python3.12/site-packages/airflow/models/baseoperator.py", line 400, in wrapper
    return func(self, *args, **kwargs)
           ^^^^^^^^^^^^^^^^^^^^^^^^^^^
  File "/home/airflow/.local/lib/python3.12/site-packages/airflow/providers/common/sql/operators/sql.py", line 282, in execute
    output = hook.run(
             ^^^^^^^^^
  File "/home/airflow/.local/lib/python3.12/site-packages/airflow/providers/common/sql/hooks/sql.py", line 404, in run
    self._run_command(cur, sql_statement, parameters)
  File "/home/airflow/.local/lib/python3.12/site-packages/airflow/providers/common/sql/hooks/sql.py", line 462, in _run_command
    cur.execute(sql_statement)
psycopg2.errors.UniqueViolation: duplicate key value violates unique constraint "pg_type_typname_nsp_index"
DETAIL:  Key (typname, typnamespace)=(dag_runs, 2200) already exists.

[2024-04-23T15:23:36.786+0000] {taskinstance.py:1205} INFO - Marking task as UP_FOR_RETRY. dag_id=dag_with_postgres_operator_v01, task_id=create_postgres_table, execution_date=20240421T000000, start_date=20240423T152336, end_date=20240423T152336
[2024-04-23T15:23:36.791+0000] {standard_task_runner.py:110} ERROR - Failed to execute job 414 for task create_postgres_table (duplicate key value violates unique constraint "pg_type_typname_nsp_index"
DETAIL:  Key (typname, typnamespace)=(dag_runs, 2200) already exists.
; 1752)
[2024-04-23T15:23:36.815+0000] {local_task_job_runner.py:240} INFO - Task exited with return code 1
[2024-04-23T15:23:36.823+0000] {taskinstance.py:3482} INFO - 0 downstream tasks scheduled from follow-on schedule check
[2024-04-23T15:23:36.824+0000] {local_task_job_runner.py:222} INFO - ::endgroup::
