[2024-04-23T21:27:42.092+0000] {local_task_job_runner.py:120} INFO - ::group::Pre task execution logs
[2024-04-23T21:27:42.109+0000] {taskinstance.py:2073} INFO - Dependencies all met for dep_context=non-requeueable deps ti=<TaskInstance: dag_with_postgres_operator_v02.insert_into_table scheduled__2024-04-21T00:00:00+00:00 [queued]>
[2024-04-23T21:27:42.113+0000] {taskinstance.py:2073} INFO - Dependencies all met for dep_context=requeueable deps ti=<TaskInstance: dag_with_postgres_operator_v02.insert_into_table scheduled__2024-04-21T00:00:00+00:00 [queued]>
[2024-04-23T21:27:42.113+0000] {taskinstance.py:2303} INFO - Starting attempt 2 of 6
[2024-04-23T21:27:42.120+0000] {taskinstance.py:2327} INFO - Executing <Task(PostgresOperator): insert_into_table> on 2024-04-21 00:00:00+00:00
[2024-04-23T21:27:42.126+0000] {standard_task_runner.py:90} INFO - Running: ['***', 'tasks', 'run', 'dag_with_postgres_operator_v02', 'insert_into_table', 'scheduled__2024-04-21T00:00:00+00:00', '--job-id', '426', '--raw', '--subdir', 'DAGS_FOLDER/dag_with_postgres_operator.py', '--cfg-path', '/tmp/tmp6sz2ypu8']
[2024-04-23T21:27:42.128+0000] {standard_task_runner.py:91} INFO - Job 426: Subtask insert_into_table
[2024-04-23T21:27:42.128+0000] {logging_mixin.py:188} WARNING - /home/***/.local/lib/python3.12/site-packages/***/task/task_runner/standard_task_runner.py:61 DeprecationWarning: This process (pid=5105) is multi-threaded, use of fork() may lead to deadlocks in the child.
[2024-04-23T21:27:42.129+0000] {standard_task_runner.py:63} INFO - Started process 5107 to run task
[2024-04-23T21:27:42.171+0000] {task_command.py:426} INFO - Running <TaskInstance: dag_with_postgres_operator_v02.insert_into_table scheduled__2024-04-21T00:00:00+00:00 [running]> on host e87e2f3305bd
[2024-04-23T21:27:42.200+0000] {abstractoperator.py:725} ERROR - Exception rendering Jinja template for task 'insert_into_table', field 'sql'. Template: "\n            insert into dag_runs (dt, dag_id) values('{{  dt  }}','{{  dag.dag_id  }}')\n        "
Traceback (most recent call last):
  File "/home/airflow/.local/lib/python3.12/site-packages/airflow/models/abstractoperator.py", line 717, in _do_render_template_fields
    rendered_content = self.render_template(
                       ^^^^^^^^^^^^^^^^^^^^^
  File "/home/airflow/.local/lib/python3.12/site-packages/airflow/template/templater.py", line 169, in render_template
    return self._render(template, context)
           ^^^^^^^^^^^^^^^^^^^^^^^^^^^^^^^
  File "/home/airflow/.local/lib/python3.12/site-packages/airflow/models/abstractoperator.py", line 675, in _render
    return super()._render(template, context, dag=dag)
           ^^^^^^^^^^^^^^^^^^^^^^^^^^^^^^^^^^^^^^^^^^^
  File "/home/airflow/.local/lib/python3.12/site-packages/airflow/template/templater.py", line 126, in _render
    return render_template_to_string(template, context)
           ^^^^^^^^^^^^^^^^^^^^^^^^^^^^^^^^^^^^^^^^^^^^
  File "/home/airflow/.local/lib/python3.12/site-packages/airflow/utils/helpers.py", line 289, in render_template_to_string
    return render_template(template, cast(MutableMapping[str, Any], context), native=False)
           ^^^^^^^^^^^^^^^^^^^^^^^^^^^^^^^^^^^^^^^^^^^^^^^^^^^^^^^^^^^^^^^^^^^^^^^^^^^^^^^^
  File "/home/airflow/.local/lib/python3.12/site-packages/airflow/utils/helpers.py", line 284, in render_template
    return "".join(nodes)
           ^^^^^^^^^^^^^^
  File "<template>", line 14, in root
  File "/home/airflow/.local/lib/python3.12/site-packages/jinja2/runtime.py", line 852, in _fail_with_undefined_error
    raise self._undefined_exception(self._undefined_message)
jinja2.exceptions.UndefinedError: 'dt' is undefined
[2024-04-23T21:27:42.202+0000] {taskinstance.py:2890} ERROR - Task failed with exception
Traceback (most recent call last):
  File "/home/airflow/.local/lib/python3.12/site-packages/airflow/models/taskinstance.py", line 2476, in _run_raw_task
    self._execute_task_with_callbacks(context, test_mode, session=session)
  File "/home/airflow/.local/lib/python3.12/site-packages/airflow/models/taskinstance.py", line 2629, in _execute_task_with_callbacks
    task_orig = self.render_templates(context=context, jinja_env=jinja_env)
                ^^^^^^^^^^^^^^^^^^^^^^^^^^^^^^^^^^^^^^^^^^^^^^^^^^^^^^^^^^^
  File "/home/airflow/.local/lib/python3.12/site-packages/airflow/models/taskinstance.py", line 3079, in render_templates
    original_task.render_template_fields(context, jinja_env)
  File "/home/airflow/.local/lib/python3.12/site-packages/airflow/models/baseoperator.py", line 1336, in render_template_fields
    self._do_render_template_fields(self, self.template_fields, context, jinja_env, set())
  File "/home/airflow/.local/lib/python3.12/site-packages/airflow/models/abstractoperator.py", line 717, in _do_render_template_fields
    rendered_content = self.render_template(
                       ^^^^^^^^^^^^^^^^^^^^^
  File "/home/airflow/.local/lib/python3.12/site-packages/airflow/template/templater.py", line 169, in render_template
    return self._render(template, context)
           ^^^^^^^^^^^^^^^^^^^^^^^^^^^^^^^
  File "/home/airflow/.local/lib/python3.12/site-packages/airflow/models/abstractoperator.py", line 675, in _render
    return super()._render(template, context, dag=dag)
           ^^^^^^^^^^^^^^^^^^^^^^^^^^^^^^^^^^^^^^^^^^^
  File "/home/airflow/.local/lib/python3.12/site-packages/airflow/template/templater.py", line 126, in _render
    return render_template_to_string(template, context)
           ^^^^^^^^^^^^^^^^^^^^^^^^^^^^^^^^^^^^^^^^^^^^
  File "/home/airflow/.local/lib/python3.12/site-packages/airflow/utils/helpers.py", line 289, in render_template_to_string
    return render_template(template, cast(MutableMapping[str, Any], context), native=False)
           ^^^^^^^^^^^^^^^^^^^^^^^^^^^^^^^^^^^^^^^^^^^^^^^^^^^^^^^^^^^^^^^^^^^^^^^^^^^^^^^^
  File "/home/airflow/.local/lib/python3.12/site-packages/airflow/utils/helpers.py", line 284, in render_template
    return "".join(nodes)
           ^^^^^^^^^^^^^^
  File "<template>", line 14, in root
  File "/home/airflow/.local/lib/python3.12/site-packages/jinja2/runtime.py", line 852, in _fail_with_undefined_error
    raise self._undefined_exception(self._undefined_message)
jinja2.exceptions.UndefinedError: 'dt' is undefined
[2024-04-23T21:27:42.213+0000] {taskinstance.py:1205} INFO - Marking task as UP_FOR_RETRY. dag_id=dag_with_postgres_operator_v02, task_id=insert_into_table, execution_date=20240421T000000, start_date=20240423T212742, end_date=20240423T212742
[2024-04-23T21:27:42.222+0000] {standard_task_runner.py:110} ERROR - Failed to execute job 426 for task insert_into_table ('dt' is undefined; 5107)
[2024-04-23T21:27:42.233+0000] {local_task_job_runner.py:240} INFO - Task exited with return code 1
[2024-04-23T21:27:42.241+0000] {taskinstance.py:3482} INFO - 0 downstream tasks scheduled from follow-on schedule check
[2024-04-23T21:27:42.242+0000] {local_task_job_runner.py:222} INFO - ::endgroup::
